Workbook

Sheet o-Ride E_730
A1: 平台負載 | B1: 1500 | C1: kg | K1: 滾珠螺桿型號 | L1: 螺桿軸外徑(mm) | M1: 螺桿螺距(mm) | N1: 珠徑, Da(mm) | O1: 動額定負荷, Ca(kgf) | P1: 靜額定負荷, Coa(kfg) | Q1: 剛性, K(kg/um) | R1: 螺帽長度, L | T1: 伺服馬達型號 | U1: 伺服驅動器型號 | V1: 額定出力容量 | W1: 額定轉矩 | X1: 最大轉矩 | Y1: 額定回轉數 | Z1: 瞬間容許轉速 | AA1: 額定電流 | AB1: 最大電流 | AC1: 重量 | AD1: 軸心直徑 | AE1: 軸心長度 | AI1: 時規皮帶輪 | AJ1: 齒數 | AK1: 皮帶寬度 | AL1: 齒輪直徑, PD | AM1: 齒輪厚度,W
A2: 螺桿側軸力, Faxial | B2: 730 | C2: kgf | D2: 6 | E2: PCS | F2: =D2*B2 -> 4380 | G2: =C2 -> kgf | I2: 102 | K2: BP016x05 SPPJ4281 | L2: 16 | M2: 5 | N2: 3 | O2: 1020 | P2: 1551 | R2: 35 | S2: SKF | T2: 110MB040A-001000 | V2: 0.4 | W2: 1000 | X2: 3.82 | Y2: 2 | Z2: 1500 | AA2: 11.5 | AB2: 6 | AC2: 5.8 | AD2: 19 | AE2: =58-5.3 -> 52.7 | AF2: SYNTRON | AI2: HTPA18S8M250-A | AJ2: 18 | AK2: 25 | AL2: 45.84 | AM2: 33
A3: 缸行程 | B3: 200 | C3: mm | K3: BRF030x05 | L3: 30 | M3: 5 | O3: 9386 | P3: 18196 | R3: 85 | S3: SKF | T3: 110MB060D-001000 | V3: 0.6 | W3: 1500 | X3: 4 | Y3: 2.6 | Z3: 2000 | AA3: 12 | AB3: 7.8 | AC3: 5.8 | AD3: 19 | AE3: =58-5.3 -> 52.7 | AF3: SYNTRON | AI3: HTPA18S8M300-A | AJ3: 18 | AK3: 30 | AL3: 45.84 | AM3: 38
A4: 安裝角度 | B4: 90 | C4: degree | K4: BRF030x06 | L4: 30 | M4: 6 | O4: 9694 | P4: 17892 | R4: 85 | S4: SKF | T4: 110MB075B-001000 | V4: 0.75 | W4: 2000 | X4: 3.58 | Y4: 3.2 | Z4: 2500 | AA4: 10.7 | AB4: 9.6 | AC4: 5.8 | AD4: 19 | AE4: =58-5.3 -> 52.7 | AF4: SYNTRON | AI4: HTPA19S8M250-A | AJ4: 19 | AK4: 25 | AL4: 48.38 | AM4: 33
A5: 導引面磨擦係數 | B5: 0.01 | K5: BRF030x10 | L5: 30 | M5: 10 | O5: 10849 | P5: 17792 | R5: 85 | S5: SKF | T5: 110MB075D-001000 | V5: 0.75 | W5: 1500 | X5: 5 | Y5: 3.2 | Z5: 2000 | AA5: 12 | AB5: 9.6 | AC5: 6.6 | AD5: 19 | AE5: =58-5.3 -> 52.7 | AF5: SYNTRON | AI5: HTPA19S8M300-A | AJ5: 19 | AK5: 30 | AL5: 48.38 | AM5: 38
K6: BRF030x20 | L6: 30 | M6: 20 | O6: 12580 | P6: 18090 | R6: 85 | S6: SKF | T6: 110MB200C-R58B11 | U6: HS200AE | V6: 2 | W6: 3000 | X6: 6.4 | Y6: 9.5 | Z6: 5000 | AA6: 19.2 | AD6: 19 | AE6: 50 | AF6: SYNTRON | AI6: HTPA20S8M250-A | AJ6: 20 | AK6: 25 | AL6: 50.93 | AM6: 33
A7: 滾珠螺桿型號 | B7: FSDC-025x10_6.35-5 | K7: BRF036x06 | L7: 30 | M7: 6 | O7: 9230 | P7: 18305 | R7: 80 | S7: SKF | T7: 130MB300C-R48B11 | U7: HS300AE | V7: 3 | W7: 2000 | X7: 15 | Y7: 11.7 | Z7: 2300 | AA7: 15 | AD7: 22 | AE7: 52 | AF7: SYNTRON | AI7: HTPA20S8M300-A | AJ7: 20 | AK7: 30 | AL7: 50.93 | AM7: 38
A8: 螺桿軸外徑, DN | B8: =INDEX($K$2:$S$187,MATCH($B$7,$K$2:$K$187),2) -> 25 | C8: mm | K8: BRF036x09 | L8: 30 | M8: 9 | O8: 9951 | P8: 17760 | R8: 80 | S8: SKF | T8: ESM060A | U8: Mini OPDE | V8: 0.4 | W8: 3000 | X8: 1.274 | Y8: 2 | Z8: 4000 | AA8: 3.822 | AB8: 6 | AC8: 2 | AD8: 14 | AE8: 27 | AF8: HPB | AI8: HTPA21S8M250-A | AJ8: 21 | AK8: 25 | AL8: 53.48 | AM8: 33
A9: 螺桿導程pitch, Ph | B9: =INDEX($K$2:$S$187,MATCH($B$7,$K$2:$K$187),3) -> 10 | C9: mm/rev | K9: BRF036x12 | L9: 30 | M9: 12 | O9: 10878 | P9: 18480 | R9: 80 | S9: SKF | T9: ESM085A | U9: Mini OPDE | V9: 0.4 | W9: 2000 | X9: 1.9 | Y9: 2.5 | Z9: 4000 | AA9: 5.7 | AB9: 7.5 | AC9: 3 | AD9: 14 | AE9: 30 | AF9: HPB | AI9: HTPA21S8M300-A | AJ9: 21 | AK9: 30 | AL9: 53.48 | AM9: 38
A10: 動額定負荷, Ca | B10: =INDEX($K$2:$S$187,MATCH($B$7,$K$2:$K$187),5) -> 5050 | C10: kgf | K10: BRF036x18 | L10: 30 | M10: 18 | O10: 11647 | P10: 18017 | R10: 80 | S10: SKF | T10: ESM085B | U10: Mini OPDE | V10: 0.6 | W10: 2000 | X10: 2.84 | Y10: 3.2 | Z10: 4000 | AA10: 8.52 | AB10: 9 | AC10: 4 | AD10: 16 | AE10: 30 | AF10: HPB | AI10: HTPA22S8M250-A | AJ10: 22 | AK10: 25 | AL10: 56.02 | AM10: 33
A11: 靜額定負荷, Coa | B11: =INDEX($K$2:$S$187,MATCH($B$7,$K$2:$K$187),6) -> 11500 | C11: kgf | K11: BRF036x24 | L11: 30 | M11: 24 | O11: 12612 | P11: 18814 | R11: 80 | S11: SKF | T11: ESM085D | U11: Mini OPDE | V11: 1 | W11: 2000 | X11: 4.8 | Y11: 5.2 | Z11: 4000 | AA11: 14.4 | AB11: 15.6 | AC11: 6 | AD11: 16 | AE11: 30 | AF11: HPB | AI11: HTPA22S8M300-A | AJ11: 22 | AK11: 30 | AL11: 56.02 | AM11: 38
A12: 剛性, K | B12: =INDEX($K$2:$S$187,MATCH($B$7,$K$2:$K$187),7) -> 72 | C12: kgf/μm | K12: BRF039x10 | L12: 39 | M12: 10 | O12: 15573 | P12: 27646 | R12: 100 | S12: SKF | T12: ESM125E-220V | U12: Mini OPDE | V12: 3 | W12: 3000 | X12: 14.3 | Y12: 10 | Z12: 4000 | AA12: 42.9 | AC12: 13 | AD12: 28 | AE12: 51 | AF12: HPB | AI12: HTPA24S8M250-A | AJ12: 24 | AK12: 25 | AL12: 61.12 | AM12: 33
A13: 滾珠螺冒長度 | B13: =INDEX($K$2:$S$187,MATCH($B$7,$K$2:$K$187),8) -> 78 | C13: mm | K13: BRF039x20 | L13: 39 | M13: 20 | O13: 17635 | P13: 26621 | R13: 100 | S13: SKF | T13: ESM125E-380V | U13: Mini OPDE | V13: 3 | W13: 3000 | X13: 14.3 | Y13: 6.7 | Z13: 4000 | AA13: 42.9 | AC13: 13 | AD13: 28 | AE13: 51 | AF13: HPB | AI13: HTPA24S8M300-A | AJ13: 24 | AK13: 30 | AL13: 61.12 | AM13: 38
A14: 滾珠螺桿總長度, L | B14: =+B3+B13+200 -> 478 | C14: mm | K14: BRF048x10 | L14: 48 | M14: 10 | O14: 23627 | P14: 48481 | R14: 127 | S14: SKF | T14: HC-RP 103(B) | U14: MR-J3 200 | V14: 1 | W14: 3000 | X14: 3.18 | Y14: 6.1 | Z14: 5175 | AA14: 7.95 | AB14: 18 | AC14: 6 | AD14: 24 | AE14: 40 | AF14: Mitsubishi | AI14: HTPA25S8M250-A | AJ14: 25 | AK14: 25 | AL14: 63.66 | AM14: 33
A15: 滾珠螺桿重量, WS | B15: =ROUND(0.25*B8^2*PI()*B14*7850/1000000000,2) -> 1.84 | C15: kg | K15: BRF048x20 | L15: 48 | M15: 20 | O15: 27111 | P15: 47170 | R15: 127 | S15: SKF | T15: HC-RP 105(B) | U15: MR-J3 200 | V15: 1.5 | W15: 3000 | X15: 4.78 | Y15: 8.8 | Z15: 5175 | AA15: 11.9 | AB15: 23 | AC15: 7 | AD15: 24 | AE15: 40 | AF15: Mitsubishi | AI15: HTPA25S8M300-A | AJ15: 25 | AK15: 30 | AL15: 63.66 | AM15: 38
K16: BRF056x12 | L16: 56 | M16: 12 | O16: 21650 | P16: 44196 | R16: 112 | S16: SKF | T16: HC-RP 203(B) | U16: MR-J3 350 | V16: 2 | W16: 3000 | X16: 6.37 | Y16: 14 | Z16: 5175 | AA16: 15.9 | AB16: 37 | AC16: 8.3 | AD16: 24 | AE16: 40 | AF16: Mitsubishi | AI16: HTPA26S8M250-A | AJ16: 26 | AK16: 25 | AL16: 66.21 | AM16: 33
A17: 最大加速度要求 | B17: 0.3 | C17: g | D17: =+B17*9.81 -> 2.943 | E17: m/s2 | F17: =+D17*1000 -> 2943 | G17: mm/s2 | K17: BRF056x24 | L17: 56 | M17: 24 | O17: 24716 | P17: 42770 | R17: 112 | S17: SKF | T17: HC-RP 353(B) | U17: MR-J3 200 | V17: 1.5 | W17: 2000 | X17: 7.16 | Y17: 8 | Z17: 3450 | AA17: 21.5 | AB17: 24 | AC17: 10.3 | AD17: 24 | AE17: 50 | AF17: Mitsubishi | AI17: HTPA26S8M300-A | AJ17: 26 | AK17: 30 | AL17: 66.21 | AM17: 38
A18: ※角度單位為 rad => 2π rad = 360º = 1 rev (rev = revolutions) | K18: BRF060x10 | L18: 60 | M18: 10 | O18: 34548 | P18: 79560 | R18: 152 | S18: SKF | T18: HC-RP 503(B) | U18: MR-J3 500 | V18: 5 | W18: 3000 | X18: 15.9 | Y18: 28 | Z18: 5175 | AA18: 39.7 | AB18: 70 | AC18: 21 | AD18: 28 | AE18: 58 | AF18: Mitsubishi | AI18: HTPA28S8M250-A | AJ18: 28 | AK18: 25 | AL18: 71.3 | AM18: 33
A19: ※角速度單位為 rad/s => 2π rad/s = 1 rev/s = 60 rev/min = 60 rpm | K19: BRF060x20 | L19: 60 | M19: 20 | O19: 40303 | P19: 80169 | R19: 152 | S19: SKF | T19: HF-SP 102(B) | U19: MR-J3 200 | V19: 3.5 | W19: 2000 | X19: 16.7 | Y19: 16 | Z19: 3450 | AA19: 50.1 | AB19: 48 | AC19: 25 | AD19: 35 | AE19: 75 | AF19: Mitsubishi | AI19: HTPA28S8M300-A | AJ19: 28 | AK19: 30 | AL19: 71.3 | AM19: 38
A20: ※角加速度單位為 rad/s2 => 2π rad/s2 = 1 rev/s2 | K20: BRF064x12 | L20: 64 | M20: 12 | O20: 30243 | P20: 77888 | R20: 129 | S20: SKF | T20: HF-SP 152(B) | U20: MR-J3 200 | V20: 1.5 | W20: 2000 | X20: 7.16 | Y20: 8 | Z20: 3450 | AA20: 21.5 | AB20: 24 | AC20: 10.3 | AD20: 24 | AE20: 50 | AF20: Mitsubishi | AI20: HTPA30S8M150-A | AJ20: 30 | AK20: 15 | AL20: 28.65 | AM20: 21
K21: BRF064x24 | L21: 64 | M21: 24 | O21: 33564 | P21: 70369 | R21: 129 | S21: SKF | T21: HF-SP 202(B) | U21: MR-J3 200 | V21: 7 | W21: 2000 | X21: 33.4 | Y21: 33 | Z21: 3450 | AA21: 100 | AB21: 99 | AC21: 38 | AD21: 35 | AE21: 75 | AF21: Mitsubishi | AI21: HTPA30S8M250-A | AJ21: 30 | AK21: 25 | AL21: 76.39 | AM21: 33
A22: 角加速度 | B22: =+F17/B9 -> 294.3 | C22: rev/s2 | D22: =+ROUND(B22*2*PI(),0) -> 1849 | E22: rad/s2 | K22: BRF075x10 | L22: 75 | M22: 10 | O22: 51516 | P22: 151702 | R22: 191 | S22: SKF | T22: HF-SP 352(B) | U22: MR-J3 200 | V22: 3.5 | W22: 2000 | X22: 16.7 | Y22: 16 | Z22: 3450 | AA22: 50.1 | AB22: 48 | AC22: 25 | AD22: 35 | AE22: 75 | AF22: Mitsubishi | AI22: HTPA30S8M300-A | AJ22: 30 | AK22: 30 | AL22: 76.39 | AM22: 38
A23: 加速時間要求 | B23: 0.01 | C23: s | K23: BRF075x20 | L23: 75 | M23: 20 | O23: 58394 | P23: 152640 | R23: 191 | S23: SKF | T23: HF-SP 502(B) | U23: MR-J3 500 | V23: 3.5 | W23: 3000 | X23: 11.1 | Y23: 23 | Z23: 5175 | AA23: 27.9 | AB23: 58 | AC23: 15 | AD23: 28 | AE23: 58 | AF23: Mitsubishi | AI23: HTPA32S8M250-A | AJ23: 32 | AK23: 25 | AL23: 81.49 | AM23: 33
A24: 最快速度要求,vmax | B24: 0.22 | C24: m/s | D24: =+B24*1000 -> 220 | E24: mm/s | F24: =+B24*60 -> 13.2 | G24: m/min | H24: =+D24*60 -> 13200 | I24: mm/min | K24: BRF080x12 | L24: 80 | M24: 12 | O24: 41864 | P24: 118690 | R24: 156 | S24: SKF | T24: HF-SP 702(B) | U24: MR-J3 200 | V24: 7 | W24: 2000 | X24: 33.4 | Y24: 33 | Z24: 3450 | AA24: 100 | AB24: 99 | AC24: 38 | AD24: 35 | AE24: 75 | AF24: Mitsubishi | AI24: HTPA32S8M300-A | AJ24: 32 | AK24: 30 | AL24: 81.49 | AM24: 38
K25: BRF080x18 | L25: 80 | M25: 18 | O25: 46524 | P25: 119146 | R25: 156 | S25: SKF | T25: HG-JR103(B)_200V | U25: MR-J4-100A/B | V25: 1 | W25: 3000 | X25: 3.2 | Y25: 5.6 | Z25: 6000 | AA25: 9.6 | AB25: 17 | AC25: 4.5 | AD25: 16 | AE25: 30 | AF25: Mitsubishi | AI25: HTPA34S8M250-A | AJ25: 34 | AK25: 25 | AL25: 86.58 | AM25: 33
A26: 伺服馬達型號 | B26: SME-L20020SDBU | K26: BRF080x24 | L26: 80 | M26: 24 | O26: 46816 | P26: 119598 | R26: 156 | S26: SKF | T26: HG-JR153(B)_200V | U26: MR-J4-200A/B | V26: 1.5 | W26: 3000 | X26: 4.8 | Y26: 11 | Z26: 6000 | AA26: 14.3 | AB26: 32 | AC26: 5.9 | AD26: 16 | AE26: 30 | AF26: Mitsubishi | AI26: HTPA34S8M300-A | AJ26: 34 | AK26: 30 | AL26: 86.58 | AM26: 38
A27: 伺服驅動器型號 | B27: =INDEX($T$2:$AF$137,MATCH($B$26,$T$2:$T$137),2) -> SDE-200A2U | K27: BRF099x20 | L27: 99 | M27: 20 | O27: 94373 | P27: 315351 | R27: 260 | S27: SKF | T27: HG-JR203(B)_200V | U27: MR-J4-200A/B | V27: 2 | W27: 3000 | X27: 6.4 | Y27: 11 | Z27: 6000 | AA27: 19.1 | AB27: 32 | AC27: 7.5 | AD27: 16 | AE27: 30 | AF27: Mitsubishi | AI27: HTPA36S8M250-A | AJ27: 36 | AK27: 25 | AL27: 91.67 | AM27: 33
A28: 額定出力容量 | B28: =INDEX($T$2:$AF$137,MATCH($B$26,$T$2:$T$137),3) -> 2 | C28: kW | K28: BRF100x24 | L28: 100 | M28: 24 | O28: 66919 | P28: 186308 | R28: 195 | S28: SKF | T28: HG-JR353(B)_200V | U28: MR-J4-350A/B | V28: 3.5 | W28: 3000 | X28: 10.5 | Y28: 17 | Z28: 6000 | AA28: 32 | AB28: 51 | AC28: 13 | AD28: 28 | AE28: 50 | AF28: Mitsubishi | AI28: HTPA36S8M300-A | AJ28: 36 | AK28: 30 | AL28: 91.67 | AM28: 38
A29: 馬達額定扭力, Tdrive | B29: =INDEX($T$2:$AF$137,MATCH($B$26,$T$2:$T$137),5) -> 9.55 | C29: N-m | K29: BRF120x24 | L29: 120 | M29: 24 | O29: 93369 | P29: 308883 | R29: 240 | S29: SKF | T29: HG-JR503(B)_200V | U29: MR-J4-500A/B | V29: 5 | W29: 3000 | X29: 15.9 | Y29: 27 | Z29: 6000 | AA29: 47.7 | AB29: 81 | AC29: 18 | AD29: 28 | AE29: 50 | AF29: Mitsubishi | AI29: HTPA38S8M250-A | AJ29: 38 | AK29: 25 | AL29: 96.77 | AM29: 33
A30: 最大轉矩 | B30: =INDEX($T$2:$AF$137,MATCH($B$26,$T$2:$T$137),8) -> 28.5 | C30: N-m | K30: BRF120x25 | L30: 120 | M30: 25 | O30: 115044 | P30: 412038 | R30: 280 | S30: SKF | T30: HG-JR53(B) | U30: MR-J4-60A/B | V30: 0.5 | W30: 3000 | X30: 1.6 | Y30: 3 | Z30: 6000 | AA30: 4.8 | AB30: 9 | AC30: 3 | AD30: 16 | AE30: 30 | AF30: Mitsubishi | AI30: HTPA38S8M300-A | AJ30: 38 | AK30: 30 | AL30: 96.77 | AM30: 38
A31: 馬達額定轉速, Rrpm | B31: =INDEX($T$2:$AF$137,MATCH($B$26,$T$2:$T$137),4) -> 2000 | C31: rpm | K31: BRF150x25 | L31: 150 | M31: 25 | O31: 162911 | P31: 695515 | R31: 400 | S31: SKF | T31: HG-JR703(B)_200V | U31: MR-J4-700A/B | V31: 7 | W31: 3000 | X31: 22.3 | Y31: 34 | Z31: 6000 | AA31: 66.8 | AB31: 103 | AC31: 29 | AD31: 35 | AE31: 75 | AF31: Mitsubishi | AI31: HTPA40S8M250-A | AJ31: 40 | AK31: 25 | AL31: 101.86 | AM31: 33
A32: 瞬間容許轉速 | B32: =INDEX($T$2:$AF$137,MATCH($B$26,$T$2:$T$137),7) -> 3500 | C32: rpm | K32: BRF150x36 | L32: 150 | M32: 36 | O32: 118053 | P32: 419193 | R32: 305 | S32: SKF | T32: HG-JR73(B) | U32: MR-J4-70A/B | V32: 0.75 | W32: 3000 | X32: 2.4 | Y32: 5.6 | Z32: 6000 | AA32: 7.2 | AB32: 17 | AC32: 3.7 | AD32: 16 | AE32: 30 | AF32: Mitsubishi | AI32: HTPA40S8M300-A | AJ32: 40 | AK32: 30 | AL32: 101.86 | AM32: 38
A33: 額定電流 | B33: =INDEX($T$2:$AF$137,MATCH($B$26,$T$2:$T$137),6) -> 11 | C33: A | K33: BRF180x30 | L33: 180 | M33: 30 | O33: 200239 | P33: 925410 | R33: 515 | S33: SKF | T33: HG-JR903(B)_200V | U33: MR-J4-11KA/B | V33: 9 | W33: 3000 | X33: 28.6 | Y33: 41 | Z33: 6000 | AA33: 85.8 | AB33: 134 | AC33: 36 | AD33: 35 | AE33: 75 | AF33: Mitsubishi | AI33: HTPA44S8M250-A | AJ33: 44 | AK33: 25 | AL33: 112.05 | AM33: 33
A34: 最大電流 | B34: =INDEX($T$2:$AF$137,MATCH($B$26,$T$2:$T$137),9) -> 33 | C34: A | K34: BRF210x30 | L34: 210 | M34: 30 | O34: 234245 | P34: 1160741 | R34: 550 | S34: SKF | T34: HG-KN43B-K(B) | U34: MR-JE-40A | V34: 0.4 | W34: 3000 | X34: 1.3 | Y34: 2.6 | Z34: 5000 | AA34: 3.8 | AB34: 7.8 | AC34: 1.9 | AD34: 14 | AE34: 26 | AF34: Mitsubishi | AI34: HTPA44S8M300-A | AJ34: 44 | AK34: 30 | AL34: 112.05 | AM34: 38
A35: 重量 | B35: =INDEX($T$2:$AF$137,MATCH($B$26,$T$2:$T$137),10) -> 9.9 | C35: kg | K35: FDWE-050x20_6.35-3.5 | L35: 50 | M35: 20 | N35: 6.35 | O35: 4560 | P35: 13230 | Q35: 149 | R35: 155 | S35: PMI | T35: HG-KR053(B) | U35: MR-J4-10A/B | V35: 0.05 | W35: 3000 | X35: 0.16 | Y35: 0.9 | Z35: 6900 | AA35: 0.56 | AB35: 3.2 | AC35: 0.54 | AD35: 8 | AE35: 21.5 | AF35: Mitsubishi | AI35: HTPA48S8M150-A | AJ35: 48 | AK35: 15 | AL35: 45.84 | AM35: 21
A36: 軸心直徑 | B36: =INDEX($T$2:$AF$137,MATCH($B$26,$T$2:$T$137),11) -> 24 | C36: mm | K36: FDWE-050x20_6.35-5 | L36: 50 | M36: 20 | N36: 6.35 | O36: 5580 | P36: 16710 | Q36: 185 | R36: 175 | S36: PMI | T36: HG-KR13(B) | U36: MR-J4-10A/B | V36: 0.1 | W36: 3000 | X36: 0.32 | Y36: 0.7 | Z36: 6900 | AA36: 1.1 | AB36: 2.5 | AC36: 0.74 | AD36: 8 | AE36: 21.5 | AF36: Mitsubishi | AI36: HTPA48S8M250-A | AJ36: 48 | AK36: 25 | AL36: 122.23 | AM36: 33
A37: 軸心長度 | B37: =INDEX($T$2:$AF$137,MATCH($B$26,$T$2:$T$137),12) -> 50 | C37: mm | K37: FEM-E-C-016x10R | L37: 16 | M37: 10 | N37: 3 | O37: 1172 | P37: 1255 | R37: 45 | S37: Rexroth | T37: HG-KR23(B) | U37: MR-J4-20A/B | V37: 0.2 | W37: 3000 | X37: 0.64 | Y37: 1.3 | Z37: 6900 | AA37: 2.2 | AB37: 4.6 | AC37: 1.3 | AD37: 14 | AE37: 26 | AF37: Mitsubishi | AI37: HTPA48S8M300-A | AJ37: 48 | AK37: 30 | AL37: 122.23 | AM37: 38
K38: FEM-E-C-016x16Rx3-4 | L38: 16 | M38: 16 | N38: 3 | O38: 1143 | P38: 1224 | R38: 61 | S38: Rexroth | T38: HG-KR43(B) | U38: MR-J4-40A/B | V38: 0.4 | W38: 3000 | X38: 1.3 | Y38: 2.6 | Z38: 6900 | AA38: 4.5 | AB38: 9.1 | AC38: 1.8 | AD38: 14 | AE38: 26 | AF38: Mitsubishi | AI38: HTPA50S8M250-A | AJ38: 50 | AK38: 25 | AL38: 127.32 | AM38: 33
A39: 伺服馬達側齒輪規格(傳動) | B39: HTPA32S8M250-A | K39: FEM-E-C-020x05Rx3-4 | L39: 20 | M39: 5 | N39: 3 | O39: 1755 | P39: 2194 | R39: 40 | S39: Rexroth | T39: HG-KR73(B) | U39: MR-J4-70A/B | V39: 0.75 | W39: 3000 | X39: 2.4 | Y39: 4.9 | Z39: 6900 | AA39: 8.4 | AB39: 17.2 | AC39: 3.8 | AD39: 19 | AE39: 36 | AF39: Mitsubishi | AI39: HTPA50S8M300-A | AJ39: 50 | AK39: 30 | AL39: 127.32 | AM39: 38
A40: 傳動側齒數, N1 | B40: =INDEX($AI$2:$AM$53,MATCH($B$39,$AI$2:$AI$53),2) -> 32 | K40: FEM-E-C-020x10Rx3-4 | L40: 20 | M40: 10 | N40: 3 | O40: 1724 | P40: 2173 | R40: 60 | S40: Rexroth | T40: HG-MR053(B) | U40: MR-J4-10A/B | V40: 0.05 | W40: 3000 | X40: 0.16 | Y40: 1 | Z40: 6900 | AA40: 0.48 | AB40: 3.1 | AC40: 0.54 | AD40: 8 | AE40: 21.5 | AF40: Mitsubishi | AI40: HTPA60S8M250-A | AJ40: 60 | AK40: 25 | AL40: 152.79 | AM40: 33
...

Sheet 扭力_730
A1: 螺桿側軸力, Faxial | B1: =+'o-Ride E_730'!B2 -> 730 | C1: kgf | D1: =+ROUND(B1*9.81,2) -> 7161.3 | E1: N
A2: 螺桿傳動機械效率, η | B2: 0.9
A3: 軸-淨輸入 | B3: =ROUND(B1/B2,2) -> 811.11 | C3: kgf | D3: =+ROUND(B3*9.81,2) -> 7956.99 | E3: N
A4: 螺桿導程pitch, Ph | B4: =+'o-Ride E_730'!B9 -> 10 | C4: mm | D4: =+B4/1000 -> 0.01 | E4: m
A5: 軸-淨輸入扭力, Taxial | B5: =+ROUND(B1*D4/(2*PI()*B2),2) -> 1.29 | C5: kgf-m | D5: =+ROUND(D1*D4/(2*PI()*B2),2) -> 12.66 | E5: N-m
A8: 皮帶傳動效率, ηpulley | B8: 0.95
A9: 馬達側皮帶輪齒數, N1 | B9: =+'o-Ride E_730'!B40 -> 32
A10: 螺桿側皮帶輪齒數, N2 | B10: =+'o-Ride E_730'!B46 -> 48
A11: 減速比(Slave/Drive), i | B11: =+B10/B9 -> 1.5
A14: 馬達扭力, Tdrive | B14: =+D5/(B11*B8) -> 8.8842105 | C14: N-m | D14: =+(D1*D4)/(2*PI()*B2*B11*B8) -> 8.8869886 | E14: N-m

Sheet 出力_730
A1: 馬達額定扭力, Tdrive | B1: =+'o-Ride E_730'!B29 -> 9.55 | C1: Nm
A2: 馬達側皮帶輪齒數, N1 | B2: =+'o-Ride E_730'!B40 -> 32
A3: 螺桿側皮帶輪齒數, N2 | B3: =+'o-Ride E_730'!B46 -> 48
A4: 減速比(Slave/Drive), i | B4: =+B3/B2 -> 1.5
A7: 皮帶傳動效率, ηpulley | B7: 0.95
A8: 螺桿側扭力, Taxial | B8: =+ROUND(B1*B4*B7,2) -> 13.61 | C8: N-m
A11: 螺桿導程, Ph | B11: ='o-Ride E_730'!B9/1000 -> 0.01 | C11: m
A12: 螺桿傳動機械效率, η | B12: 0.9
A13: 螺桿側軸力, Faxial | B13: =ROUND(2*PI()*B12*B8/B11,2) -> 7696.27 | C13: N | D13: =+ROUND(B13/9.81,2) -> 784.53 | E13: kgf | G13: =ROUND(2*PI()*B12*B1*B4*B7/B11,2) -> 7695.57 | H13: N

Sheet o-Ride E_500
A1: 平台負載 | B1: 1500 | C1: kg | K1: 滾珠螺桿型號 | L1: 螺桿軸外徑(mm) | M1: 螺桿螺距(mm) | N1: 珠徑, Da(mm) | O1: 動額定負荷, Ca(kgf) | P1: 靜額定負荷, Coa(kfg) | Q1: 剛性, K(kg/um) | R1: 螺帽長度, L | T1: 伺服馬達型號 | U1: 伺服驅動器型號 | V1: 額定出力容量 | W1: 額定轉矩 | X1: 最大轉矩 | Y1: 額定回轉數 | Z1: 瞬間容許轉速 | AA1: 額定電流 | AB1: 最大電流 | AC1: 重量 | AD1: 軸心直徑 | AE1: 軸心長度 | AI1: 時規皮帶輪 | AJ1: 齒數 | AK1: 皮帶寬度 | AL1: 齒輪直徑, PD | AM1: 齒輪厚度,W
A2: 螺桿側軸力, Faxial | B2: 500 | C2: kgf | D2: 6 | E2: PCS | F2: =D2*B2 -> 3000 | G2: =C2 -> kgf | I2: 102 | K2: BP016x05 SPPJ4281 | L2: 16 | M2: 5 | N2: 3 | O2: 1020 | P2: 1551 | R2: 35 | S2: SKF | T2: 110MB040A-001000 | V2: 0.4 | W2: 1000 | X2: 3.82 | Y2: 2 | Z2: 1500 | AA2: 11.5 | AB2: 6 | AC2: 5.8 | AD2: 19 | AE2: =58-5.3 -> 52.7 | AF2: SYNTRON | AI2: HTPA18S8M250-A | AJ2: 18 | AK2: 25 | AL2: 45.84 | AM2: 33
A3: 缸行程 | B3: 200 | C3: mm | K3: BRF030x05 | L3: 30 | M3: 5 | O3: 9386 | P3: 18196 | R3: 85 | S3: SKF | T3: 110MB060D-001000 | V3: 0.6 | W3: 1500 | X3: 4 | Y3: 2.6 | Z3: 2000 | AA3: 12 | AB3: 7.8 | AC3: 5.8 | AD3: 19 | AE3: =58-5.3 -> 52.7 | AF3: SYNTRON | AI3: HTPA18S8M300-A | AJ3: 18 | AK3: 30 | AL3: 45.84 | AM3: 38
A4: 安裝角度 | B4: 90 | C4: degree | K4: BRF030x06 | L4: 30 | M4: 6 | O4: 9694 | P4: 17892 | R4: 85 | S4: SKF | T4: 110MB075B-001000 | V4: 0.75 | W4: 2000 | X4: 3.58 | Y4: 3.2 | Z4: 2500 | AA4: 10.7 | AB4: 9.6 | AC4: 5.8 | AD4: 19 | AE4: =58-5.3 -> 52.7 | AF4: SYNTRON | AI4: HTPA19S8M250-A | AJ4: 19 | AK4: 25 | AL4: 48.38 | AM4: 33
A5: 導引面磨擦係數 | B5: 0.01 | K5: BRF030x10 | L5: 30 | M5: 10 | O5: 10849 | P5: 17792 | R5: 85 | S5: SKF | T5: 110MB075D-001000 | V5: 0.75 | W5: 1500 | X5: 5 | Y5: 3.2 | Z5: 2000 | AA5: 12 | AB5: 9.6 | AC5: 6.6 | AD5: 19 | AE5: =58-5.3 -> 52.7 | AF5: SYNTRON | AI5: HTPA19S8M300-A | AJ5: 19 | AK5: 30 | AL5: 48.38 | AM5: 38
K6: BRF030x20 | L6: 30 | M6: 20 | O6: 12580 | P6: 18090 | R6: 85 | S6: SKF | T6: 110MB200C-R58B11 | U6: HS200AE | V6: 2 | W6: 3000 | X6: 6.4 | Y6: 9.5 | Z6: 5000 | AA6: 19.2 | AD6: 19 | AE6: 50 | AF6: SYNTRON | AI6: HTPA20S8M250-A | AJ6: 20 | AK6: 25 | AL6: 50.93 | AM6: 33
A7: 滾珠螺桿型號 | B7: FSDC-020x10_4.762-4 | K7: BRF036x06 | L7: 30 | M7: 6 | O7: 9230 | P7: 18305 | R7: 80 | S7: SKF | T7: 130MB300C-R48B11 | U7: HS300AE | V7: 3 | W7: 2000 | X7: 15 | Y7: 11.7 | Z7: 2300 | AA7: 15 | AD7: 22 | AE7: 52 | AF7: SYNTRON | AI7: HTPA20S8M300-A | AJ7: 20 | AK7: 30 | AL7: 50.93 | AM7: 38
A8: 螺桿軸外徑, DN | B8: =INDEX($K$2:$S$187,MATCH($B$7,$K$2:$K$187),2) -> 20 | C8: mm | K8: BRF036x09 | L8: 30 | M8: 9 | O8: 9951 | P8: 17760 | R8: 80 | S8: SKF | T8: ESM060A | U8: Mini OPDE | V8: 0.4 | W8: 3000 | X8: 1.274 | Y8: 2 | Z8: 4000 | AA8: 3.822 | AB8: 6 | AC8: 2 | AD8: 14 | AE8: 27 | AF8: HPB | AI8: HTPA21S8M250-A | AJ8: 21 | AK8: 25 | AL8: 53.48 | AM8: 33
A9: 螺桿導程pitch, Ph | B9: =INDEX($K$2:$S$187,MATCH($B$7,$K$2:$K$187),3) -> 10 | C9: mm/rev | K9: BRF036x12 | L9: 30 | M9: 12 | O9: 10878 | P9: 18480 | R9: 80 | S9: SKF | T9: ESM085A | U9: Mini OPDE | V9: 0.4 | W9: 2000 | X9: 1.9 | Y9: 2.5 | Z9: 4000 | AA9: 5.7 | AB9: 7.5 | AC9: 3 | AD9: 14 | AE9: 30 | AF9: HPB | AI9: HTPA21S8M300-A | AJ9: 21 | AK9: 30 | AL9: 53.48 | AM9: 38
A10: 動額定負荷, Ca | B10: =INDEX($K$2:$S$187,MATCH($B$7,$K$2:$K$187),5) -> 2560 | C10: kgf | K10: BRF036x18 | L10: 30 | M10: 18 | O10: 11647 | P10: 18017 | R10: 80 | S10: SKF | T10: ESM085B | U10: Mini OPDE | V10: 0.6 | W10: 2000 | X10: 2.84 | Y10: 3.2 | Z10: 4000 | AA10: 8.52 | AB10: 9 | AC10: 4 | AD10: 16 | AE10: 30 | AF10: HPB | AI10: HTPA22S8M250-A | AJ10: 22 | AK10: 25 | AL10: 56.02 | AM10: 33
A11: 靜額定負荷, Coa | B11: =INDEX($K$2:$S$187,MATCH($B$7,$K$2:$K$187),6) -> 5530 | C11: kgf | K11: BRF036x24 | L11: 30 | M11: 24 | O11: 12612 | P11: 18814 | R11: 80 | S11: SKF | T11: ESM085D | U11: Mini OPDE | V11: 1 | W11: 2000 | X11: 4.8 | Y11: 5.2 | Z11: 4000 | AA11: 14.4 | AB11: 15.6 | AC11: 6 | AD11: 16 | AE11: 30 | AF11: HPB | AI11: HTPA22S8M300-A | AJ11: 22 | AK11: 30 | AL11: 56.02 | AM11: 38
A12: 剛性, K | B12: =INDEX($K$2:$S$187,MATCH($B$7,$K$2:$K$187),7) -> 47 | C12: kgf/μm | K12: BRF039x10 | L12: 39 | M12: 10 | O12: 15573 | P12: 27646 | R12: 100 | S12: SKF | T12: ESM125E-220V | U12: Mini OPDE | V12: 3 | W12: 3000 | X12: 14.3 | Y12: 10 | Z12: 4000 | AA12: 42.9 | AC12: 13 | AD12: 28 | AE12: 51 | AF12: HPB | AI12: HTPA24S8M250-A | AJ12: 24 | AK12: 25 | AL12: 61.12 | AM12: 33
A13: 滾珠螺冒長度 | B13: =INDEX($K$2:$S$187,MATCH($B$7,$K$2:$K$187),8) -> 62 | C13: mm | K13: BRF039x20 | L13: 39 | M13: 20 | O13: 17635 | P13: 26621 | R13: 100 | S13: SKF | T13: ESM125E-380V | U13: Mini OPDE | V13: 3 | W13: 3000 | X13: 14.3 | Y13: 6.7 | Z13: 4000 | AA13: 42.9 | AC13: 13 | AD13: 28 | AE13: 51 | AF13: HPB | AI13: HTPA24S8M300-A | AJ13: 24 | AK13: 30 | AL13: 61.12 | AM13: 38
A14: 滾珠螺桿總長度, L | B14: =+B3+B13+200 -> 462 | C14: mm | K14: BRF048x10 | L14: 48 | M14: 10 | O14: 23627 | P14: 48481 | R14: 127 | S14: SKF | T14: HC-RP 103(B) | U14: MR-J3 200 | V14: 1 | W14: 3000 | X14: 3.18 | Y14: 6.1 | Z14: 5175 | AA14: 7.95 | AB14: 18 | AC14: 6 | AD14: 24 | AE14: 40 | AF14: Mitsubishi | AI14: HTPA25S8M250-A | AJ14: 25 | AK14: 25 | AL14: 63.66 | AM14: 33
A15: 滾珠螺桿重量, WS | B15: =ROUND(0.25*B8^2*PI()*B14*7850/1000000000,2) -> 1.14 | C15: kg | K15: BRF048x20 | L15: 48 | M15: 20 | O15: 27111 | P15: 47170 | R15: 127 | S15: SKF | T15: HC-RP 105(B) | U15: MR-J3 200 | V15: 1.5 | W15: 3000 | X15: 4.78 | Y15: 8.8 | Z15: 5175 | AA15: 11.9 | AB15: 23 | AC15: 7 | AD15: 24 | AE15: 40 | AF15: Mitsubishi | AI15: HTPA25S8M300-A | AJ15: 25 | AK15: 30 | AL15: 63.66 | AM15: 38
K16: BRF056x12 | L16: 56 | M16: 12 | O16: 21650 | P16: 44196 | R16: 112 | S16: SKF | T16: HC-RP 203(B) | U16: MR-J3 350 | V16: 2 | W16: 3000 | X16: 6.37 | Y16: 14 | Z16: 5175 | AA16: 15.9 | AB16: 37 | AC16: 8.3 | AD16: 24 | AE16: 40 | AF16: Mitsubishi | AI16: HTPA26S8M250-A | AJ16: 26 | AK16: 25 | AL16: 66.21 | AM16: 33
A17: 最大加速度要求 | B17: 0.2 | C17: g | D17: =+B17*9.81 -> 1.962 | E17: m/s2 | F17: =+D17*1000 -> 1962 | G17: mm/s2 | K17: BRF056x24 | L17: 56 | M17: 24 | O17: 24716 | P17: 42770 | R17: 112 | S17: SKF | T17: HC-RP 353(B) | U17: MR-J3 200 | V17: 1.5 | W17: 2000 | X17: 7.16 | Y17: 8 | Z17: 3450 | AA17: 21.5 | AB17: 24 | AC17: 10.3 | AD17: 24 | AE17: 50 | AF17: Mitsubishi | AI17: HTPA26S8M300-A | AJ17: 26 | AK17: 30 | AL17: 66.21 | AM17: 38
A18: ※角度單位為 rad => 2π rad = 360º = 1 rev (rev = revolutions) | K18: BRF060x10 | L18: 60 | M18: 10 | O18: 34548 | P18: 79560 | R18: 152 | S18: SKF | T18: HC-RP 503(B) | U18: MR-J3 500 | V18: 5 | W18: 3000 | X18: 15.9 | Y18: 28 | Z18: 5175 | AA18: 39.7 | AB18: 70 | AC18: 21 | AD18: 28 | AE18: 58 | AF18: Mitsubishi | AI18: HTPA28S8M250-A | AJ18: 28 | AK18: 25 | AL18: 71.3 | AM18: 33
A19: ※角速度單位為 rad/s => 2π rad/s = 1 rev/s = 60 rev/min = 60 rpm | K19: BRF060x20 | L19: 60 | M19: 20 | O19: 40303 | P19: 80169 | R19: 152 | S19: SKF | T19: HF-SP 102(B) | U19: MR-J3 200 | V19: 3.5 | W19: 2000 | X19: 16.7 | Y19: 16 | Z19: 3450 | AA19: 50.1 | AB19: 48 | AC19: 25 | AD19: 35 | AE19: 75 | AF19: Mitsubishi | AI19: HTPA28S8M300-A | AJ19: 28 | AK19: 30 | AL19: 71.3 | AM19: 38
A20: ※角加速度單位為 rad/s2 => 2π rad/s2 = 1 rev/s2 | K20: BRF064x12 | L20: 64 | M20: 12 | O20: 30243 | P20: 77888 | R20: 129 | S20: SKF | T20: HF-SP 152(B) | U20: MR-J3 200 | V20: 1.5 | W20: 2000 | X20: 7.16 | Y20: 8 | Z20: 3450 | AA20: 21.5 | AB20: 24 | AC20: 10.3 | AD20: 24 | AE20: 50 | AF20: Mitsubishi | AI20: HTPA30S8M150-A | AJ20: 30 | AK20: 15 | AL20: 28.65 | AM20: 21
K21: BRF064x24 | L21: 64 | M21: 24 | O21: 33564 | P21: 70369 | R21: 129 | S21: SKF | T21: HF-SP 202(B) | U21: MR-J3 200 | V21: 7 | W21: 2000 | X21: 33.4 | Y21: 33 | Z21: 3450 | AA21: 100 | AB21: 99 | AC21: 38 | AD21: 35 | AE21: 75 | AF21: Mitsubishi | AI21: HTPA30S8M250-A | AJ21: 30 | AK21: 25 | AL21: 76.39 | AM21: 33
A22: 角加速度 | B22: =+F17/B9 -> 196.2 | C22: rev/s2 | D22: =+ROUND(B22*2*PI(),0) -> 1233 | E22: rad/s2 | K22: BRF075x10 | L22: 75 | M22: 10 | O22: 51516 | P22: 151702 | R22: 191 | S22: SKF | T22: HF-SP 352(B) | U22: MR-J3 200 | V22: 3.5 | W22: 2000 | X22: 16.7 | Y22: 16 | Z22: 3450 | AA22: 50.1 | AB22: 48 | AC22: 25 | AD22: 35 | AE22: 75 | AF22: Mitsubishi | AI22: HTPA30S8M300-A | AJ22: 30 | AK22: 30 | AL22: 76.39 | AM22: 38
A23: 加速時間要求 | B23: 0.01 | C23: s | K23: BRF075x20 | L23: 75 | M23: 20 | O23: 58394 | P23: 152640 | R23: 191 | S23: SKF | T23: HF-SP 502(B) | U23: MR-J3 500 | V23: 3.5 | W23: 3000 | X23: 11.1 | Y23: 23 | Z23: 5175 | AA23: 27.9 | AB23: 58 | AC23: 15 | AD23: 28 | AE23: 58 | AF23: Mitsubishi | AI23: HTPA32S8M250-A | AJ23: 32 | AK23: 25 | AL23: 81.49 | AM23: 33
A24: 最快速度要求 | B24: 0.2 | C24: m/s | D24: =+B24*1000 -> 200 | E24: mm/s | F24: =+B24*60 -> 12 | G24: m/min | H24: =+D24*60 -> 12000 | I24: mm/min | K24: BRF080x12 | L24: 80 | M24: 12 | O24: 41864 | P24: 118690 | R24: 156 | S24: SKF | T24: HF-SP 702(B) | U24: MR-J3 200 | V24: 7 | W24: 2000 | X24: 33.4 | Y24: 33 | Z24: 3450 | AA24: 100 | AB24: 99 | AC24: 38 | AD24: 35 | AE24: 75 | AF24: Mitsubishi | AI24: HTPA32S8M300-A | AJ24: 32 | AK24: 30 | AL24: 81.49 | AM24: 38
K25: BRF080x18 | L25: 80 | M25: 18 | O25: 46524 | P25: 119146 | R25: 156 | S25: SKF | T25: HG-JR103(B)_200V | U25: MR-J4-100A/B | V25: 1 | W25: 3000 | X25: 3.2 | Y25: 5.6 | Z25: 6000 | AA25: 9.6 | AB25: 17 | AC25: 4.5 | AD25: 16 | AE25: 30 | AF25: Mitsubishi | AI25: HTPA34S8M250-A | AJ25: 34 | AK25: 25 | AL25: 86.58 | AM25: 33
A26: 伺服馬達型號 | B26: 110MB200C-R58B11 | K26: BRF080x24 | L26: 80 | M26: 24 | O26: 46816 | P26: 119598 | R26: 156 | S26: SKF | T26: HG-JR153(B)_200V | U26: MR-J4-200A/B | V26: 1.5 | W26: 3000 | X26: 4.8 | Y26: 11 | Z26: 6000 | AA26: 14.3 | AB26: 32 | AC26: 5.9 | AD26: 16 | AE26: 30 | AF26: Mitsubishi | AI26: HTPA34S8M300-A | AJ26: 34 | AK26: 30 | AL26: 86.58 | AM26: 38
A27: 伺服驅動器型號 | B27: =INDEX($T$2:$AF$137,MATCH($B$26,$T$2:$T$137),2) -> HS200AE | K27: BRF099x20 | L27: 99 | M27: 20 | O27: 94373 | P27: 315351 | R27: 260 | S27: SKF | T27: HG-JR203(B)_200V | U27: MR-J4-200A/B | V27: 2 | W27: 3000 | X27: 6.4 | Y27: 11 | Z27: 6000 | AA27: 19.1 | AB27: 32 | AC27: 7.5 | AD27: 16 | AE27: 30 | AF27: Mitsubishi | AI27: HTPA36S8M250-A | AJ27: 36 | AK27: 25 | AL27: 91.67 | AM27: 33
A28: 額定出力容量 | B28: =INDEX($T$2:$AF$137,MATCH($B$26,$T$2:$T$137),3) -> 2 | C28: kW | K28: BRF100x24 | L28: 100 | M28: 24 | O28: 66919 | P28: 186308 | R28: 195 | S28: SKF | T28: HG-JR353(B)_200V | U28: MR-J4-350A/B | V28: 3.5 | W28: 3000 | X28: 10.5 | Y28: 17 | Z28: 6000 | AA28: 32 | AB28: 51 | AC28: 13 | AD28: 28 | AE28: 50 | AF28: Mitsubishi | AI28: HTPA36S8M300-A | AJ28: 36 | AK28: 30 | AL28: 91.67 | AM28: 38
A29: 馬達額定扭力, Tdrive | B29: =INDEX($T$2:$AF$137,MATCH($B$26,$T$2:$T$137),5) -> 6.4 | C29: N-m | K29: BRF120x24 | L29: 120 | M29: 24 | O29: 93369 | P29: 308883 | R29: 240 | S29: SKF | T29: HG-JR503(B)_200V | U29: MR-J4-500A/B | V29: 5 | W29: 3000 | X29: 15.9 | Y29: 27 | Z29: 6000 | AA29: 47.7 | AB29: 81 | AC29: 18 | AD29: 28 | AE29: 50 | AF29: Mitsubishi | AI29: HTPA38S8M250-A | AJ29: 38 | AK29: 25 | AL29: 96.77 | AM29: 33
A30: 最大轉矩 | B30: =INDEX($T$2:$AF$137,MATCH($B$26,$T$2:$T$137),8) -> 19.2 | C30: N-m | K30: BRF120x25 | L30: 120 | M30: 25 | O30: 115044 | P30: 412038 | R30: 280 | S30: SKF | T30: HG-JR53(B) | U30: MR-J4-60A/B | V30: 0.5 | W30: 3000 | X30: 1.6 | Y30: 3 | Z30: 6000 | AA30: 4.8 | AB30: 9 | AC30: 3 | AD30: 16 | AE30: 30 | AF30: Mitsubishi | AI30: HTPA38S8M300-A | AJ30: 38 | AK30: 30 | AL30: 96.77 | AM30: 38
A31: 馬達額定轉速, Rrpm | B31: =INDEX($T$2:$AF$137,MATCH($B$26,$T$2:$T$137),4) -> 3000 | C31: rpm | K31: BRF150x25 | L31: 150 | M31: 25 | O31: 162911 | P31: 695515 | R31: 400 | S31: SKF | T31: HG-JR703(B)_200V | U31: MR-J4-700A/B | V31: 7 | W31: 3000 | X31: 22.3 | Y31: 34 | Z31: 6000 | AA31: 66.8 | AB31: 103 | AC31: 29 | AD31: 35 | AE31: 75 | AF31: Mitsubishi | AI31: HTPA40S8M250-A | AJ31: 40 | AK31: 25 | AL31: 101.86 | AM31: 33
A32: 瞬間容許轉速 | B32: =INDEX($T$2:$AF$137,MATCH($B$26,$T$2:$T$137),7) -> 5000 | C32: rpm | K32: BRF150x36 | L32: 150 | M32: 36 | O32: 118053 | P32: 419193 | R32: 305 | S32: SKF | T32: HG-JR73(B) | U32: MR-J4-70A/B | V32: 0.75 | W32: 3000 | X32: 2.4 | Y32: 5.6 | Z32: 6000 | AA32: 7.2 | AB32: 17 | AC32: 3.7 | AD32: 16 | AE32: 30 | AF32: Mitsubishi | AI32: HTPA40S8M300-A | AJ32: 40 | AK32: 30 | AL32: 101.86 | AM32: 38
A33: 額定電流 | B33: =INDEX($T$2:$AF$137,MATCH($B$26,$T$2:$T$137),6) -> 9.5 | C33: A | K33: BRF180x30 | L33: 180 | M33: 30 | O33: 200239 | P33: 925410 | R33: 515 | S33: SKF | T33: HG-JR903(B)_200V | U33: MR-J4-11KA/B | V33: 9 | W33: 3000 | X33: 28.6 | Y33: 41 | Z33: 6000 | AA33: 85.8 | AB33: 134 | AC33: 36 | AD33: 35 | AE33: 75 | AF33: Mitsubishi | AI33: HTPA44S8M250-A | AJ33: 44 | AK33: 25 | AL33: 112.05 | AM33: 33
A34: 最大電流 | B34: =INDEX($T$2:$AF$137,MATCH($B$26,$T$2:$T$137),9) -> 0 | C34: A | K34: BRF210x30 | L34: 210 | M34: 30 | O34: 234245 | P34: 1160741 | R34: 550 | S34: SKF | T34: HG-KN43B-K(B) | U34: MR-JE-40A | V34: 0.4 | W34: 3000 | X34: 1.3 | Y34: 2.6 | Z34: 5000 | AA34: 3.8 | AB34: 7.8 | AC34: 1.9 | AD34: 14 | AE34: 26 | AF34: Mitsubishi | AI34: HTPA44S8M300-A | AJ34: 44 | AK34: 30 | AL34: 112.05 | AM34: 38
A35: 重量 | B35: =INDEX($T$2:$AF$137,MATCH($B$26,$T$2:$T$137),10) -> 0 | C35: kg | K35: FDWE-050x20_6.35-3.5 | L35: 50 | M35: 20 | N35: 6.35 | O35: 4560 | P35: 13230 | Q35: 149 | R35: 155 | S35: PMI | T35: HG-KR053(B) | U35: MR-J4-10A/B | V35: 0.05 | W35: 3000 | X35: 0.16 | Y35: 0.9 | Z35: 6900 | AA35: 0.56 | AB35: 3.2 | AC35: 0.54 | AD35: 8 | AE35: 21.5 | AF35: Mitsubishi | AI35: HTPA48S8M150-A | AJ35: 48 | AK35: 15 | AL35: 45.84 | AM35: 21
A36: 軸心直徑 | B36: =INDEX($T$2:$AF$137,MATCH($B$26,$T$2:$T$137),11) -> 19 | C36: mm | K36: FDWE-050x20_6.35-5 | L36: 50 | M36: 20 | N36: 6.35 | O36: 5580 | P36: 16710 | Q36: 185 | R36: 175 | S36: PMI | T36: HG-KR13(B) | U36: MR-J4-10A/B | V36: 0.1 | W36: 3000 | X36: 0.32 | Y36: 0.7 | Z36: 6900 | AA36: 1.1 | AB36: 2.5 | AC36: 0.74 | AD36: 8 | AE36: 21.5 | AF36: Mitsubishi | AI36: HTPA48S8M250-A | AJ36: 48 | AK36: 25 | AL36: 122.23 | AM36: 33
A37: 軸心長度 | B37: =INDEX($T$2:$AF$137,MATCH($B$26,$T$2:$T$137),12) -> 50 | C37: mm | K37: FEM-E-C-016x10R | L37: 16 | M37: 10 | N37: 3 | O37: 1172 | P37: 1255 | R37: 45 | S37: Rexroth | T37: HG-KR23(B) | U37: MR-J4-20A/B | V37: 0.2 | W37: 3000 | X37: 0.64 | Y37: 1.3 | Z37: 6900 | AA37: 2.2 | AB37: 4.6 | AC37: 1.3 | AD37: 14 | AE37: 26 | AF37: Mitsubishi | AI37: HTPA48S8M300-A | AJ37: 48 | AK37: 30 | AL37: 122.23 | AM37: 38
K38: FEM-E-C-016x16Rx3-4 | L38: 16 | M38: 16 | N38: 3 | O38: 1143 | P38: 1224 | R38: 61 | S38: Rexroth | T38: HG-KR43(B) | U38: MR-J4-40A/B | V38: 0.4 | W38: 3000 | X38: 1.3 | Y38: 2.6 | Z38: 6900 | AA38: 4.5 | AB38: 9.1 | AC38: 1.8 | AD38: 14 | AE38: 26 | AF38: Mitsubishi | AI38: HTPA50S8M250-A | AJ38: 50 | AK38: 25 | AL38: 127.32 | AM38: 33
A39: 伺服馬達側齒輪規格(傳動) | B39: HTPA32S8M250-A | K39: FEM-E-C-020x05Rx3-4 | L39: 20 | M39: 5 | N39: 3 | O39: 1755 | P39: 2194 | R39: 40 | S39: Rexroth | T39: HG-KR73(B) | U39: MR-J4-70A/B | V39: 0.75 | W39: 3000 | X39: 2.4 | Y39: 4.9 | Z39: 6900 | AA39: 8.4 | AB39: 17.2 | AC39: 3.8 | AD39: 19 | AE39: 36 | AF39: Mitsubishi | AI39: HTPA50S8M300-A | AJ39: 50 | AK39: 30 | AL39: 127.32 | AM39: 38
A40: 傳動側齒數, N1 | B40: =INDEX($AI$2:$AM$54,MATCH($B$39,$AI$2:$AI$54),2) -> 32 | K40: FEM-E-C-020x10Rx3-4 | L40: 20 | M40: 10 | N40: 3 | O40: 1724 | P40: 2173 | R40: 60 | S40: Rexroth | T40: HG-MR053(B) | U40: MR-J4-10A/B | V40: 0.05 | W40: 3000 | X40: 0.16 | Y40: 1 | Z40: 6900 | AA40: 0.48 | AB40: 3.1 | AC40: 0.54 | AD40: 8 | AE40: 21.5 | AF40: Mitsubishi | AI40: HTPA60S8M250-A | AJ40: 60 | AK40: 25 | AL40: 152.79 | AM40: 33
...

Sheet 扭力_500
A1: 螺桿側軸力, Faxial | B1: =+'o-Ride E_500'!B2 -> 500 | C1: kgf | D1: =+ROUND(B1*9.81,2) -> 4905 | E1: N
A2: 螺桿傳動機械效率, η | B2: 0.9
A3: 軸-淨輸入 | B3: =ROUND(B1/B2,2) -> 555.56 | C3: kgf | D3: =+ROUND(B3*9.81,2) -> 5450.04 | E3: N
A4: 螺桿導程pitch, Ph | B4: =+'o-Ride E_500'!B9 -> 10 | C4: mm | D4: =+B4/1000 -> 0.01 | E4: m
A5: 軸-淨輸入扭力, Taxial | B5: =+ROUND(B1*D4/(2*PI()*B2),2) -> 0.88 | C5: kgf-m | D5: =+ROUND(D1*D4/(2*PI()*B2),2) -> 8.67 | E5: N-m
A8: 皮帶傳動效率, ηpulley | B8: 0.95
A9: 馬達側皮帶輪齒數, N1 | B9: =+'o-Ride E_500'!B40 -> 32
A10: 螺桿側皮帶輪齒數, N2 | B10: =+'o-Ride E_500'!B46 -> 48
A11: 減速比(Slave/Drive), i | B11: =+B10/B9 -> 1.5
A14: 馬達扭力, Tdrive | B14: =+D5/(B11*B8) -> 6.0842105 | C14: N-m | D14: =+(D1*D4)/(2*PI()*B2*B11*B8) -> 6.0869785 | E14: N-m

Sheet 出力_500
A1: 馬達額定扭力, Tdrive | B1: =+'o-Ride E_500'!B29 -> 6.4 | C1: Nm
A2: 馬達側皮帶輪齒數, N1 | B2: =+'o-Ride E_500'!B40 -> 32
A3: 螺桿側皮帶輪齒數, N2 | B3: =+'o-Ride E_500'!B46 -> 48
A4: 減速比(Slave/Drive), i | B4: =+B3/B2 -> 1.5
A7: 皮帶傳動效率, ηpulley | B7: 0.95
A8: 螺桿側扭力, Taxial | B8: =+ROUND(B1*B4*B7,2) -> 9.12 | C8: N-m
A11: 螺桿導程, Ph | B11: ='o-Ride E_500'!B9/1000 -> 0.01 | C11: m
A12: 螺桿傳動機械效率, η | B12: 0.9
A13: 螺桿側軸力, Faxial | B13: =ROUND(2*PI()*B12*B8/B11,2) -> 5157.24 | C13: N | D13: =+ROUND(B13/9.81,2) -> 525.71 | E13: kgf | G13: =ROUND(2*PI()*B12*B1*B4*B7/B11,2) -> 5157.24 | H13: N

Sheet 計算公式
A1: 螺桿側軸力, Faxial | B1: N
A2: 馬達額定扭力, Tdrive | B2: Nm
A3: 螺桿側扭力, Taxial | B3: Nm
A4: 馬達額定轉速, Rrpm | B4: rev
A5: 電機功率, PkW | B5: kW
A6: 螺桿導程pitch, Ph | B6: m
A7: 傳動側齒數, N1
A8: 從動側齒數, N2
A9: 減速比(Slave/Drive), i
A10: 螺桿傳動機械效率, η | B10: 0.8
A11: 皮帶傳動效率, ηpulley | B11: 0.95
